# 错误处理

在 Go 语言中，最常用的方法是返回多个值，其中有一个值包含错误信息，当这个错误为 `nil` 的时候，说明没有发生错误。

例如：

```go
func div(a, b float64) (float64, error) {
    if b == 0 {
        return 0, errors.New("b 不能为 0。")
    }

    result := a / b
    return result, nil
}
```

上面的函数，就定义了一个除法运算，如果 `b` 的值为 `0` 的时候，`error` 就会包含一个 `b 不能为 0。` 的错误信息。

`errors.New(string)`用于创建一个错误信息，传入的第一个参数就是错误信息。

```go
result, err := div(9, 3)
```

上面的调用结果，`result` 为 `3`， `err` 为 `nil`。

```go
result, err := div(2, 0)
```

上面的调用结果中，`err` 不为 `nil`。此时，不管 `result` 是什么值，都不应该被采纳。

使用 `fmt.Print(err)` 可以输出 `err` 中包含的错误信息。

我们也可以使用下面的形式来更灵活地处理各种情况：

```go
result, err := div(a, b)
if err != nil {
    fmt.Println("发生了错误")
    fmt.Print(err)
} else {
    fmt.Printf("运算结果为：%v", result)
}
```

## error 类型

`error` 类型是一个内置的接口类型。

```go
type error interface {
    Error() string
}
```

所以，只要我们的自定义类型满足扩展了 `Error()` 方法，并且返回值是一个 `string` 类型，那么就可以当作是一个 `error` 类型。

## panic

```go
panic(错误消息)
```

会直接引发恐慌，并附带一个错误信息。
引发恐慌之后，程序不会继续运行，但是会执行之前的所有 `defer`。

## recover

在 `panic` 之后，如果执行 `defer` 的函数时，函数中定义了 `recover` 则可以修复 `panic` 继续运行程序。

`recover()` 函数会返回引发 `panic` 的错误信息。

```go
defer func() {
    if e := recover(); e != nil {
        fmt.Println(e)
    }
}()
```